<?xml version="1.0"?>
<robot xmlns:xacro="http://www.ros.org/wiki/xacro"  name="YahboomRobot">

  <material name="white">
        <color rgba="1 1 1 1"/>
    </material>

    <material name="black">
        <color rgba="0 0 0 1"/>
    </material>

    <material name="blue">
        <color rgba="0 0 0.8 1"/>
    </material>

    <material name="red">
        <color rgba="0.8 0 0 1"/>
    </material>
    
    <link
    name="base_link">
    <inertial>
      <origin
        xyz="-0.0065246 0.00083805 0.022571"
        rpy="0 0 0" />
      <mass
        value="1" />
      <inertia
        ixx="0.0029"
        ixy="0"
        ixz="0"
        iyy="0.0117"
        iyz="0"  
        izz="0.0137" />
    </inertial>
    <visual>
      <origin
        xyz="0 0 0"
        rpy="0 0 0" />
      <geometry>
        <mesh
          filename="package://modelo_robot/meshes/chassis.STL" />
      </geometry>
      <material
        name="white">
      </material>
    </visual>
    <collision>
      <origin
        xyz="0 0 0"
        rpy="0 0 0" />
      <geometry>
        <mesh
          filename="package://modelo_robot/meshes/chassis.STL" />
      </geometry>
    </collision>
  </link>
  <link
    name="prisma_link">
    <inertial>
      <origin
        xyz="0.0035326 0 0.049545"
        rpy="0 0 0" />
      <mass
        value="0.65139" />
      <inertia
        ixx="0.0028986855"
        ixy="0"
        ixz="0"
        iyy="0.0028986855"
        iyz="0"
        izz="0.001628475" />
    </inertial>
    <visual>
      <origin
        xyz="0 0 -0.035"
        rpy="0 0 0" />
      <geometry>
        <mesh
          filename="package://modelo_robot/meshes/prisma_link.STL" />
      </geometry>
      <material
        name="blue">
      </material>
    </visual>
    <collision>
      <origin
        xyz="0 0 0"
        rpy="0 0 0" />
      <geometry>
        <mesh
          filename="package://modelo_robot/meshes/prisma_link.STL" />
      </geometry>
    </collision>
  </link>
  <joint
    name="prisma_joint"
    type="prismatic">
    <origin
      xyz="0.067648 0 0.013"
      rpy="0 0 3.1416" />
    <parent
      link="base_link" />
    <child
      link="prisma_link" />
    <axis
      xyz="0 0 1" />
    <limit
      lower="0"
      upper="0.025"
      effort="100"
      velocity="100" />
    <dynamics
      damping="10"
      friction="10" />
  </joint>
  <link
    name="base_cam_link">
    <inertial>
      <origin
        xyz="0 -2.7756E-17 0.0049838"
        rpy="0 0 0" />
      <mass
        value="0.4" />
      <inertia
        ixx="0.0004"
        ixy="0"
        ixz="0"
        iyy="0.0004"
        iyz="0"
        izz="0.00064" />
    </inertial>
    <visual>
      <origin
        xyz="0 0 0"
        rpy="0 0 0.25" />
      <geometry>
        <mesh
          filename="package://modelo_robot/meshes/base_cam_link.STL" />
      </geometry>
      <material
        name="white">
      </material>
    </visual>
    <collision>
      <origin
        xyz="0 0 0"
        rpy="0 0 0" />
      <geometry>
        <mesh
          filename="package://modelo_robot/meshes/base_cam_link.STL" />
      </geometry>
    </collision>
  </link>
  <joint
    name="base_cam_joint"
    type="revolute">
    <origin
      xyz="0.0125 0 0.1"
      rpy="0 0 0.08" />
    <parent
      link="prisma_link" />
    <child
      link="base_cam_link" />
    <axis
      xyz="0 0 1" />
    <limit
      lower="-1.5"
      upper="1.5"
      effort="100"
      velocity="100" />
    <dynamics
      damping="0.1"
      friction="0.1" />
  </joint>
  <link
    name="cam_link">
    <inertial>
      <origin
        xyz="-0.014554 -0.00083985 -1.4443"
        rpy="0 0 0" />
      <mass
        value="0.357" />
      <inertia
        ixx="0.000357"
        ixy="0"
        ixz="0"
        iyy="0.00073185"
        iyz="0"
        izz="0.00051765" />
    </inertial>
    <visual>
      <origin
        xyz="0.0005 0 0"
        rpy="1.5707 0 3.2" />
      <geometry>
        <mesh
          filename="package://modelo_robot/meshes/cam_link.STL" />
      </geometry>
      <material
        name="red">
      </material>
    </visual>
    <collision>
      <origin
        xyz="0 0 0"
        rpy="0 0 0" />
      <geometry>
        <mesh
          filename="package://modelo_robot/meshes/cam_link.STL" />
      </geometry>
    </collision>
  </link>
  <joint
    name="cam_joint"
    type="revolute">
    <origin
      xyz="0 0 0.01"
      rpy="3.1416 3.1416 -0.15" />
    <parent
      link="base_cam_link" />
    <child
      link="cam_link" />
    <axis
      xyz="0 1 0" />
    <limit
      lower="-0.5"
      upper="0.4"
      effort="100"
      velocity="100" />
    <dynamics
      damping="0.1"
      friction="0.1" />
  </joint>
  <link
    name="der_del_link">
    <inertial>
      <origin
        xyz="2.0817 -1.0408 -2.4896"
        rpy="0 0 0" />
      <mass
        value="0.15" />
      <inertia
        ixx="0.000035"
        ixy="0"
        ixz="0"
        iyy="0.000035"
        iyz="0"
        izz="0.00003" />
    </inertial>
    <visual>
      <origin
        xyz="0 0 0"
        rpy="0 0 0" />
      <geometry>
        <mesh
          filename="package://modelo_robot/meshes/der_del_link.STL" />
      </geometry>
      <material
        name="black">
      </material>
    </visual>
    <collision>
      <origin
        xyz="0 0 0"
        rpy="0 0 0" />
      <geometry>
        <mesh
          filename="package://modelo_robot/meshes/der_del_link.STL" />
      </geometry>
    </collision>
  </link>
  <joint
    name="izq_del_joint"
    type="continuous">
    <origin
      xyz="0.050556 0.047804 -0.015"
      rpy="1.5708 0 0" />
    <parent
      link="base_link" />
    <child
      link="der_del_link" />
    <axis
      xyz="0 0 1" />
    <limit
      effort="100"
      velocity="100" />
    <dynamics
      damping="0.1"
      friction="0.1" />
  </joint>
  <link
    name="izq_del_link">
    <inertial>
      <origin
        xyz="-2.7756 6.9389 2.4896"
        rpy="0 0 0" />
      <mass
        value="0.15" />
      <inertia
        ixx="0.000035"
        ixy="0"
        ixz="0"
        iyy="0.000035"
        iyz="0"
        izz="0.00003" />
    </inertial>
    <visual>
      <origin
        xyz="0 0 0"
        rpy="0 0 0" />
      <geometry>
        <mesh
          filename="package://modelo_robot/meshes/izq_del_link.STL" />
      </geometry>
      <material
        name="black">
      </material>
    </visual>
    <collision>
      <origin
        xyz="0 0 0"
        rpy="0 0 0" />
      <geometry>
        <mesh
          filename="package://modelo_robot/meshes/izq_del_link.STL" />
      </geometry>
    </collision>
  </link>
  <joint
    name="der_del_joint"
    type="continuous">
    <origin
      xyz="0.050556 -0.046806 -0.015"
      rpy="1.5708 0 0" />
    <parent
      link="base_link" />
    <child
      link="izq_del_link" />
    <axis
      xyz="0 0 1" />
    <limit
      effort="100"
      velocity="100" />
    <dynamics
      damping="0.1"
      friction="0.1" />
  </joint>
  <link
    name="izq_atras_link">
    <inertial>
      <origin
        xyz="0 0 0"
        rpy="0 0 0" />
      <mass
        value="0.15" />
      <inertia
        ixx="0.000035"
        ixy="0"
        ixz="0"
        iyy="0.000035"
        iyz="0"
        izz="0.00003" />
    </inertial>
    <visual>
      <origin
        xyz="0.10338 0 0.0946"
        rpy="0 0 0" />
      <geometry>
        <mesh
          filename="package://modelo_robot/meshes/izq_atras_link.STL" />
      </geometry>
      <material
        name="black">
      </material>
    </visual>
    <collision>
      <origin
        xyz="0 0 0"
        rpy="0 0 0" />
      <geometry>
        <mesh
          filename="package://modelo_robot/meshes/izq_atras_link.STL" />
      </geometry>
    </collision>
  </link>
  <joint
    name="izq_atras_joint"
    type="continuous">
    <origin
      xyz="-0.052704 0.047799 -0.015"
      rpy="1.5707 0 0" />
    <parent
      link="base_link" />
    <child
      link="izq_atras_link" />
    <axis
      xyz="0 0 1" />
    <limit
      effort="100"
      velocity="100" />
    <dynamics
      damping="0.1"
      friction="0.1" />
  </joint>
  <link
    name="der_atras_link">
    <inertial>
      <origin
        xyz="0 0 0"
        rpy="0 0 0" />
      <mass
        value="0.15" />
      <inertia
        ixx="0.000035"
        ixy="0"
        ixz="0"
        iyy="0.000035"
        iyz="0"
        izz="0.00003" />
    </inertial>
    <visual>
      <origin
        xyz="0.1033 0 0"
        rpy="0 0 0" />
      <geometry>
        <mesh
          filename="package://modelo_robot/meshes/der_atras_link.STL" />
      </geometry>
      <material
        name="black">
      </material>
    </visual>
    <collision>
      <origin
        xyz="0 0 0"
        rpy="0 0 0" />
      <geometry>
        <mesh
          filename="package://modelo_robot/meshes/der_atras_link.STL" />
      </geometry>
    </collision>
  </link>
  <joint
    name="der_atras_joint"
    type="continuous">
    <origin
      xyz="-0.052704 -0.046801 -0.015"
      rpy="1.5708 0 0" />
    <parent
      link="base_link" />
    <child
      link="der_atras_link" />
    <axis
      xyz="0 0 1" />
    <limit
      effort="100"
      velocity="100" />
    <dynamics
      damping="0.1"
      friction="0.1" />
  </joint>

    <xacro:include filename="gazebo.xacro" />


</robot>
